Workbook

Sheet 花名册
A1: 农民工花名册
A3: 编制单位： | F3: 45870
A4: 序号 | B4: 姓名 | C4: 性别 | D4: 民族 | E4: 籍贯 | F4: 身份证号码 | G4: 工资卡号 | H4: 开户行 | I4: 工种 | J4: 上场时间 | K4: 撤场时间 | L4: 联系电话 | M4: 备注
A5: 1 | B5: 陈罗宏 | C5: 男 | D5: 汉 | E5: 湖南省华容县梅田湖 | F5: 430623197201192213 | G5: 6236683520010069982 | H5: 三亚建设支行 | I5: 砌砖 | L5: 18689852329
A6: 2 | B6: 邓金香 | C6: 女 | D6: 汉 | E6: 湖南省华容县梅田湖 | F6: 422423197312231528 | G6: 6217003520008554279 | H6: 三亚建没支行 | I6: 砌砖 | L6: 18289568949
A7: 3 | B7: 陈国红 | C7: 男 | D7: 汉 | E7: 湖南省华容县梅田湖 | F7: 430623196810132211 | G7: 6217003520017024231 | H7: 三亚建设支行 | I7: 砌砖 | L7: 13138900510
A8: 4 | B8: 李治安 | C8: =IF(MOD(MID(F8,17,1),2)=1,"男","女") -> 男 | D8: 汉 | E8: 湖南省常德市澧县 | F8: 430723198309292814 | G8: 6217003520007698432 | H8: 海南三亚迎宾支行 | I8: 砌砖 | L8: 18569133960
A9: 5 | B9: 胡艳 | C9: =IF(MOD(MID(F9,17,1),2)=1,"男","女") -> 女 | D9: 汉 | E9: 湖南省常德市临澧县 | F9: 43072419880818542X | G9: 6217003520007698424 | H9: 海南三亚迎宾支行 | I9: 砌砖 | L9: 18673628336
A10: 6 | B10: 阳梦姣 | C10: =IF(MOD(MID(F10,17,1),2)=1,"男","女") -> 女 | D10: 汉 | E10: 湖南省湘西州花垣县 | F10: 43312419920815582X | G10: 6236683000004290621 | H10: 湖南澧县建设支行 | I10: 砌砖 | L10: 19389855242
A11: 7 | B11: 张孝庆 | C11: =IF(MOD(MID(F11,17,1),2)=1,"男","女") -> 男 | D11: 汉 | E11: 湖南省常德市桃源县 | F11: 432427197411043538 | G11: 6217003520012305239 | H11: 三亚河西支行 | I11: 砌砖 | L11: 17336594682
A12: 8 | B12: 龚德权 | C12: =IF(MOD(MID(F12,17,1),2)=1,"男","女") -> 男 | D12: 土家 | E12: 湖南省常德市石门县 | F12: 430726197911133511 | G12: 6236683520010371685 | H12: 定安支行 | I12: 砌砖 | L12: 17763637948
A13: 9 | B13: 曹承文 | C13: =IF(MOD(MID(F13,17,1),2)=1,"男","女") -> 男 | D13: 汉 | E13: 湖南省常德市澧县 | F13: 430723196810182214 | G13: 6236683520006371400 | H13: 三亚建设支行 | I13: 砌砖 | L13: 18789378078
A14: 10 | B14: 曹阳 | C14: =IF(MOD(MID(F14,17,1),2)=1,"男","女") -> 男 | D14: 汉 | E14: 湖南省常德市澧县 | F14: 430723199010272215 | G14: 6215340303001126239 | H14: 五指山建设支行 | I14: 砌砖 | L14: 18173687131
A15: 11 | B15: 陈克兰 | C15: =IF(MOD(MID(F15,17,1),2)=1,"男","女") -> 女 | D15: 汉 | E15: 湖南省常德市澧县 | F15: 430723196912085044 | G15: 6236683000002012316 | H15: 澧县建设支行 | I15: 砌砖 | L15: 18390651916
A16: 12 | B16: 黄道文 | C16: =IF(MOD(MID(F16,17,1),2)=1,"男","女") -> 男 | D16: 汉 | E16: 湖南省常德市桃源县 | F16: 432424196810235015 | G16: 6215340303714770687 | H16: 澧县建设支行 | I16: 砌砖 | L16: 13637687985
A17: 13 | B17: 雷义元 | C17: =IF(MOD(MID(F17,17,1),2)=1,"男","女") -> 男 | D17: 汉 | E17: 湖北省宜昌市兴山县 | F17: 422423197103216014 | G17: 6217003520014539751 | H17: 海口丽晶支行 | I17: 砌砖 | L17: 13647515398
A18: 14 | B18: 杨松艳 | C18: =IF(MOD(MID(F18,17,1),2)=1,"男","女") -> 女 | D18: 汉 | E18: 湖北省宜昌市兴山县 | F18: 422423197207286025 | G18: 6217003520008219071 | H18: 洋浦支行 | I18: 砌砖 | L18: 13647151935
A19: 15 | B19: 杨荣友 | C19: =IF(MOD(MID(F19,17,1),2)=1,"男","女") -> 男 | D19: 汉 | E19: 湖北省荆州市公安县 | F19: 42102219690221365X | G19: 6217003520004643027 | H19: 三亚河西支行 | I19: 砌砖 | L19: 18789585305
... A24: 20 | B24: 罗妹香 | C24: =IF(MOD(MID(F24,17,1),2)=1,"男","女") -> 女 | D24: 汉 | E24: 海南省陵水黎族自治县 | F24: 46003419860807504X | G24: 6236683520005046359 | H24: 建设陵水支行 | I24: 砌砖 | L24: 17744850109
A25: 21 | B25: 曾元清 | C25: =IF(MOD(MID(F25,17,1),2)=1,"男","女") -> 男 | D25: 汉 | E25: 湖南省常德市桃源县 | F25: 432424197210242232 | G25: 6230943520000131221 | H25: 陵水县清水湾支行 | I25: 砌砖 | L25: 15009064409
A26: 22 | B26: 向兵 | C26: =IF(MOD(MID(F26,17,1),2)=1,"男","女") -> 男 | D26: 汉 | E26: 贵州省铜仁地区思南县 | F26: 52222519861025041X | G26: 6236687180000839054 | H26: 铜仁市南长城支行 | I26: 砌砖 | L26: 13229882978
A27: 23 | B27: 曾辉 | C27: =IF(MOD(MID(F27,17,1),2)=1,"男","女") -> 男 | D27: 汉 | E27: 湖南省常德市澧县 | F27: 430723200702170012 | G27: 6217003520024505156 | H27: 陵水支行 | I27: 砌砖 | L27: 15607605073
A28: 24 | B28: 熊延支 | C28: =IF(MOD(MID(F28,17,1),2)=1,"男","女") -> 女 | D28: 汉 | E28: 湖南省常德市桃源县 | F28: 432424197107092221 | G28: 6230943520000131213 | H28: 清水湾支行 | I28: 砌砖 | L28: 15573167675
A29: 25 | B29: 王希文 | C29: =IF(MOD(MID(F29,17,1),2)=1,"男","女") -> 男 | D29: 汉 | E29: 云南省曲靖市罗平县 | F29: 530324197908221915 | G29: 6217001820047561752 | H29: 长乐市漳港支行 | I29: 砌砖 | L29: 18182924809
A30: 26 | B30: 黄汝桃 | C30: =IF(MOD(MID(F30,17,1),2)=1,"男","女") -> 女 | D30: 汉 | E30: 云南省曲靖市罗平县 | F30: 530324197602141728 | G30: 6217001830049502860 | H30: 泉州市石狮支行 | I30: 砌砖 | L30: 13278784071
A31: 27 | B31: 黄乔昌 | C31: =IF(MOD(MID(F31,17,1),2)=1,"男","女") -> 男 | D31: 汉 | E31: 云南省曲靖市罗平县 | F31: 530324198007241710 | G31: 6217003520024506337 | H31: 陵水支行 | I31: 砌砖 | L31: 15288008213
A32: 28 | B32: 刘巧芬 | C32: =IF(MOD(MID(F32,17,1),2)=1,"男","女") -> 女 | D32: 汉 | E32: 云南省曲靖市罗平县 | F32: 530324198505061747 | G32: 6217003520024505628 | H32: 陵水支行 | I32: 砌砖 | L32: 14787427760
A33: 29 | B33: 陈云山 | C33: =IF(MOD(MID(F33,17,1),2)=1,"男","女") -> 男 | D33: 汉 | E33: 河南省新乡市新乡县 | F33: 410721198404053575 | G33: 6217003520011446711 | H33: 临城镇建设支行 | I33: 砌砖 | L33: 13613906680
A34: 30 | B34: 陈升英 | C34: =IF(MOD(MID(F34,17,1),2)=1,"男","女") -> 女 | D34: 汉 | E34: 广东省湛江市廉江市 | F34: 440822197803052724 | G34: 6217003520024869552 | H34: 陵水建设支行 | I34: 砌砖 | L34: 13434679286
A35: 31 | B35: 张武平 | C35: =IF(MOD(MID(F35,17,1),2)=1,"男","女") -> 男 | D35: 汉 | E35: 四川省达州市宣汉县 | F35: 513022196609073719 | G35: 6217002120018527885 | H35: 赣州振兴支行 | I35: 砌砖 | L35: 15760684711
A36: 32 | B36: 杨国春 | C36: =IF(MOD(MID(F36,17,1),2)=1,"男","女") -> 男 | D36: 汉 | E36: 四川省达州市宣汉县 | F36: 513022199505142971 | G36: 6217003690008319567 | H36: 达州市南外支行 | I36: 砌砖 | L36: 18381843960
A37: 33 | B37: 李奎 | C37: =IF(MOD(MID(F37,17,1),2)=1,"男","女") -> 男 | D37: 汉 | E37: 云南省曲靖市罗平县 | F37: 530324199110231953 | G37: 6217003890012665126 | H37: 曲靖市支行 | I37: 砌砖 | L37: 15987450830
... A42: 38 | B42: 赵丹 | C42: =IF(MOD(MID(F42,17,1),2)=1,"男","女") -> 女 | D42: 汉 | E42: 湖南省常德市澧县 | F42: 430723199006102221 | G42: 6217003520023580325 | H42: 三亚荔枝沟支行 | I42: 砌砖 | L42: 18175608751
A43: 39 | B43: 孙桂芳 | C43: =IF(MOD(MID(F43,17,1),2)=1,"男","女") -> 女 | D43: 汉 | E43: 四川省宣汉县天生镇马蹄村5组99号 | F43: 513022199308153006 | G43: 6236683520009198255 | H43: 海南省乐东黎族自治县乐东之行 | I43: 砌砖 | L43: 18381843950
A44: 40 | B44: 李灿 | C44: =IF(MOD(MID(F44,17,1),2)=1,"男","女") -> 女 | D44: 汉 | E44: 湖北省公安县藕池镇积玉村一组 | F44: 421022200012090626 | G44: 6236683520010906977 | H44: 陵水支行 | I44: 砌砖 | L44: 15927959801
A45: 41 | B45: 许三香 | C45: =IF(MOD(MID(F45,17,1),2)=1,"男","女") -> 女 | D45: 汉 | E45: 湖北省公安县黄山头镇北宫中学院内 | F45: 421022197511201605 | G45: 6236683520010907165 | H45: 陵水支行 | I45: 砌砖 | L45: 17364257662
A46: 42 | B46: 谢志朋 | C46: =IF(MOD(MID(F46,17,1),2)=1,"男","女") -> 男 | D46: 汉 | E46: 湖南省益阳市赫山区泉交河镇枫树坝村响堂山村民 组 | F46: 432321197401232139 | G46: 6217002920138111936 | H46: 益阳桃花仑建设支行 | I46: 砌砖 | L46: 13467872097
A47: 43 | B47: 蔡良其 | C47: =IF(MOD(MID(F47,17,1),2)=1,"男","女") -> 男 | D47: 汉 | E47: 湖南省安乡县三岔河镇枞住址杨树村2组022号 | F47: 430721197208114616 | G47: 6215340303723694555 | H47: 安乡建设支行 | I47: 砌砖 | L47: 18890737388
A48: 44 | B48: 王国洪 | C48: =IF(MOD(MID(F48,17,1),2)=1,"男","女") -> 男 | D48: 汉 | E48: 湖北省监利市汴河镇到口村8-01号 | F48: 421023197008044151 | G48: 6217003520023617952 | H48: 万宁建设支行 | I48: 砌砖 | L48: 13437222112
A49: 45 | B49: 胡家波 | C49: =IF(MOD(MID(F49,17,1),2)=1,"男","女") -> 女 | D49: 汉 | E49: 湖北省孝感市孝南区尚港 镇叶万村八组 | F49: 420902198010135942 | G49: 6236683520007006864 | H49: 三亚建设支行 | I49: 砌砖 | L49: 18572122155
...

Sheet 工资表
A1: 工资表
A2: 编制单位名称：
A3: 序号 | B3: 姓名 | C3: 身份证号 | D3: 银行卡号 | E3: 账户银行 | F3: 出勤 天数 | G3: 工资标准 | H3: 应发工资 | I3: 应扣减金额 | J3: 实发 金额 | K3: 领款人签字 | L3: 备注
A4: 1 | B4: =花名册!B5 -> 陈罗宏 | C4: =花名册!F5 -> 430623197201192213 | D4: =花名册!G5 -> 6236683520010069982 | E4: =花名册!H5 -> 三亚建设支行 | J4: 4000
A5: 2 | B5: =花名册!B6 -> 邓金香 | C5: =花名册!F6 -> 422423197312231528 | D5: =花名册!G6 -> 6217003520008554279 | E5: =花名册!H6 -> 三亚建没支行 | J5: 3000
A6: 3 | B6: =花名册!B7 -> 陈国红 | C6: =花名册!F7 -> 430623196810132211 | D6: =花名册!G7 -> 6217003520017024231 | E6: =花名册!H7 -> 三亚建设支行 | J6: 4000
A7: 4 | B7: =花名册!B8 -> 李治安 | C7: =花名册!F8 -> 430723198309292814 | D7: =花名册!G8 -> 6217003520007698432 | E7: =花名册!H8 -> 海南三亚迎宾支行 | J7: 4000
A8: 5 | B8: =花名册!B9 -> 胡艳 | C8: =花名册!F9 -> 43072419880818542X | D8: =花名册!G9 -> 6217003520007698424 | E8: =花名册!H9 -> 海南三亚迎宾支行 | J8: 4000
A9: 6 | B9: =花名册!B10 -> 阳梦姣 | C9: =花名册!F10 -> 43312419920815582X | D9: =花名册!G10 -> 6236683000004290621 | E9: =花名册!H10 -> 湖南澧县建设支行 | J9: 4000
A10: 7 | B10: =花名册!B11 -> 张孝庆 | C10: =花名册!F11 -> 432427197411043538 | D10: =花名册!G11 -> 6217003520012305239 | E10: =花名册!H11 -> 三亚河西支行 | J10: 4000
A11: 8 | B11: =花名册!B12 -> 龚德权 | C11: =花名册!F12 -> 430726197911133511 | D11: =花名册!G12 -> 6236683520010371685 | E11: =花名册!H12 -> 定安支行 | J11: 4400
A12: 9 | B12: =花名册!B13 -> 曹承文 | C12: =花名册!F13 -> 430723196810182214 | D12: =花名册!G13 -> 6236683520006371400 | E12: =花名册!H13 -> 三亚建设支行 | J12: 4000
A13: 10 | B13: =花名册!B14 -> 曹阳 | C13: =花名册!F14 -> 430723199010272215 | D13: =花名册!G14 -> 6215340303001126239 | E13: =花名册!H14 -> 五指山建设支行 | J13: 4000
A14: 11 | B14: =花名册!B15 -> 陈克兰 | C14: =花名册!F15 -> 430723196912085044 | D14: =花名册!G15 -> 6236683000002012316 | E14: =花名册!H15 -> 澧县建设支行 | J14: 4000
A15: 12 | B15: =花名册!B16 -> 黄道文 | C15: =花名册!F16 -> 432424196810235015 | D15: =花名册!G16 -> 6215340303714770687 | E15: =花名册!H16 -> 澧县建设支行 | J15: 4000
... A50: 47 | B50: =花名册!B51 -> 谭勇 | C50: =花名册!F51 -> 430723198608010071 | D50: =花名册!G51 -> 6217003520024351569 | E50: =花名册!H51 -> 五指山建设支行 | J50: 3000
A51: 合计 | J51: =SUBTOTAL(9,J4:J50) -> 202800

Sheet 考勤表
A1: 农民工考勤表
A2: 编制单位： | L2: 45900
A3: 序号 | B3: 姓名 | C3: 身份证号 | D3: 1 | E3: 2 | F3: 3 | G3: 4 | H3: 5 | I3: 6 | J3: 7 | K3: 8 | L3: 9 | M3: 10 | N3: 11 | O3: 12 | P3: 13 | Q3: 14 | R3: 15 | S3: 16 | T3: 17 | U3: 18 | V3: 19 | W3: 20 | X3: 21 | Y3: 22 | Z3: 23 | AA3: 24 | AB3: 25 | AC3: 26 | AD3: 27 | AE3: 28 | AF3: 29 | AG3: 30 | AH3: 31
A4: 1
A5: 2
A6: 3
A7: 4
A8: 5
A9: 6
A10: 7
A11: 8
A12: 9
A13: 10
A14: 11
A15: 12
... A24: 21
